<?xml version="1.0"?>
<robot xmlns:xacro="http://www.ros.org/wiki/xacro" name="wheel">

    <xacro:include filename="$(find robot_description)/urdf/properties.xacro"/>
    

    <xacro:macro name="wheel" params="name traslation rotation parent">

        <link name="${name}_wheel">

            <!-- physic parameter for Gazebo-->
            <inertial>
                <origin xyz="${WHEEL_COM_XYZ}" rpy="0 0 0"/>
                <mass value="${WHEEL_M}"/>
                <inertia ixx="${WHEEL_IXX}" ixy="${WHEEL_IXY}" ixz="${WHEEL_IXZ}" iyy="${WHEEL_IYY}" iyz="${WHEEL_IYZ}" izz="${WHEEL_IZZ}"/>
            </inertial>

            <!-- import wheel.STL file and set position-->
            <visual>
                <origin xyz="0.0 0.0 0.0" rpy="0.0 0.0 0.0"/>
                <geometry>
                    <mesh filename="package://robot_description/meshes/stl/wheel.STL"/>
                    <!-- <cylinder radius="${WHEEL_RADIUS}" length="0.04"/> -->
                </geometry>
            </visual>

            <!--add colition -->
            <collision>
                <origin xyz="0.0 0.0 0.0" rpy="0.0 0.0 0.0"/>
                <geometry>
                    <cylinder radius="0.08" length="0.04"/>
                </geometry> 
            </collision> 

        </link>

        
        <!-- defind joint wheel-->
        <joint name="${name}_wheel_joint" type="continuous">
            <origin xyz="${traslation}" rpy="${rotation}"/>
            <parent link="${parent}"/>
            <child link="${name}_wheel"/>
            <axis xyz="0.0 0.0 -1.0"/>
            <limit effort="${U_MAX}" velocity="${V_MAX}"/>
            <dynamics damping="${WHEEL_JOINT_DAMP}"/>  
        </joint>

    </xacro:macro>

</robot>